<mujoco model="Classroom_Final_Fixed">
    <compiler angle="degree" coordinate="local" inertiafromgeom="true"/>
    <option timestep="0.005" gravity="0 0 -9.81"/>

    <visual>
        <quality shadowsize="8192" offsamples="8"/>
        <rgba haze="0.4 0.35 0.3 1"/>
        <global azimuth="150" elevation="-25"/>
    </visual>

    <asset>
        <texture name="tex_floor" type="2d" builtin="checker" rgb1="0.5 0.35 0.2" rgb2="0.45 0.3 0.15" width="512" height="512"/>
        <texture name="tex_wood" type="cube" builtin="flat" rgb1="0.5 0.3 0.1" width="512" height="512"/>
        <texture name="tex_wood_floor" type="2d" builtin="flat" rgb1="0.45 0.28 0.12" width="512" height="512" mark="edge" markrgb="0.35 0.22 0.1"/>
        <material name="mat_floor" texture="tex_wood_floor" texrepeat="8 8" reflectance="0.05" shininess="0.2"/>
        <material name="mat_wood" texture="tex_wood" reflectance="0.02" shininess="0.1"/>
        <material name="mat_lamp" rgba="1 1 0.9 1" emission="1"/>
        <material name="mat_blackboard" rgba="0.1 0.15 0.1 1" shininess="0.3"/>
        <material name="mat_screen" rgba="0.95 0.95 0.95 1" reflectance="0.1"/>
        <material name="mat_metal" rgba="0.6 0.6 0.65 1" shininess="0.8" reflectance="0.3"/>
        <material name="mat_plastic" rgba="0.2 0.2 0.2 1" shininess="0.5"/>
        <material name="mat_wall" rgba="0.92 0.90 0.85 1" shininess="0.1"/>
        <material name="mat_glass" rgba="0.7 0.85 0.95 0.4" shininess="0.8" reflectance="0.2"/>
    </asset>

    <worldbody>
        <light directional="true" pos="-5 8 3" dir="1 -0.8 -0.4" diffuse="0.8 0.5 0.2" castshadow="true"/>
        <light directional="true" pos="10 -5 8" dir="-1 0.5 -0.8" diffuse="0.6 0.7 0.8" castshadow="false"/>

        <geom name="floor" size="10 10 0.1" type="plane" material="mat_floor"/>

        <!-- 天花板灯具 -->
        <body name="lamp_1" pos="2.5 0 2.8">
            <geom type="cylinder" size="0.15 0.03" material="mat_lamp"/>
            <light name="light_1" pos="0 0 -0.1" dir="0 0 -1" diffuse="0.6 0.6 0.5" cutoff="45" castshadow="true"/>
        </body>
        <body name="lamp_2" pos="-0.5 0 2.8">
            <geom type="cylinder" size="0.15 0.03" material="mat_lamp"/>
            <light name="light_2" pos="0 0 -0.1" dir="0 0 -1" diffuse="0.6 0.6 0.5" cutoff="45" castshadow="true"/>
        </body>
        <body name="lamp_3" pos="-3.5 0 2.8">
            <geom type="cylinder" size="0.15 0.03" material="mat_lamp"/>
            <light name="light_3" pos="0 0 -0.1" dir="0 0 -1" diffuse="0.6 0.6 0.5" cutoff="45" castshadow="true"/>
        </body>
        <body name="lamp_4" pos="1.0 3 2.8">
            <geom type="cylinder" size="0.15 0.03" material="mat_lamp"/>
            <light name="light_4" pos="0 0 -0.1" dir="0 0 -1" diffuse="0.6 0.6 0.5" cutoff="45" castshadow="true"/>
        </body>
        <body name="lamp_5" pos="1.0 -3 2.8">
            <geom type="cylinder" size="0.15 0.03" material="mat_lamp"/>
            <light name="light_5" pos="0 0 -0.1" dir="0 0 -1" diffuse="0.6 0.6 0.5" cutoff="45" castshadow="true"/>
        </body>

        <!-- 墙壁 -->
        <!-- 前墙（讲台侧，带黑板） -->
        <geom name="front_wall" type="box" size="0.1 6 3" pos="5.8 0 3" material="mat_wall"/>

        <!-- 后墙（学生后面） -->
        <geom name="back_wall" type="box" size="0.1 6 3" pos="-5.8 0 3" material="mat_wall"/>

        <!-- 门框 -->
        <geom name="door_frame_left" type="box" size="0.1 0.05 1.0" pos="-5.75 -0.5 1.0" material="mat_wood"/>
        <geom name="door_frame_right" type="box" size="0.1 0.05 1.0" pos="-5.75 0.5 1.0" material="mat_wood"/>
        <geom name="door_frame_top" type="box" size="0.1 0.55 0.05" pos="-5.75 0 2.0" material="mat_wood"/>

        <!-- 可开关的木门 -->
        <body name="wooden_door" pos="-5.7 -0.5 0.05">
            <joint name="door_hinge" type="hinge" axis="0 0 1" pos="0 0 0" range="0 120" damping="2"/>
            <geom name="door_panel" type="box" size="0.03 0.45 0.95" pos="0 0.45 0.95" material="mat_wood" mass="15"/>
            <geom name="door_handle" type="cylinder" size="0.02 0.08" pos="0.05 0.8 1.0" quat="0.707 0 0.707 0" material="mat_metal" mass="0.3"/>
        </body>

        <!-- 左墙 -->
        <geom name="left_wall" type="box" size="6 0.1 3" pos="0 -6 3" material="mat_wall"/>

        <!-- 右墙（分段，为窗户留空） -->
        <!-- 右墙下段（窗户下方，从地面到窗户底部） -->
        <geom name="right_wall_bottom" type="box" size="6 0.1 0.75" pos="0 6 0.75" material="mat_wall"/>

        <!-- 右墙上段（窗户上方，从窗户顶部到天花板） -->
        <geom name="right_wall_top" type="box" size="6 0.1 1.25" pos="0 6 4.75" material="mat_wall"/>

        <!-- 窗户之间的墙段 -->
        <geom name="right_wall_segment1" type="box" size="1.0 0.1 1.0" pos="4.5 6 2.5" material="mat_wall"/>
        <geom name="right_wall_segment2" type="box" size="0.45 0.1 1.0" pos="1.75 6 2.5" material="mat_wall"/>
        <geom name="right_wall_segment3" type="box" size="0.45 0.1 1.0" pos="-0.75 6 2.5" material="mat_wall"/>
        <geom name="right_wall_segment4" type="box" size="0.45 0.1 1.0" pos="-3.25 6 2.5" material="mat_wall"/>
        <geom name="right_wall_segment5" type="box" size="0.7 0.1 1.0" pos="-5.65 6 2.5" material="mat_wall"/>

        <!-- 窗户（在右墙上） -->
        <!-- 窗户1 -->
        <geom name="window_frame_1" type="box" size="0.8 0.05 1.0" pos="3 5.95 2.5" material="mat_wood"/>
        <geom name="window_glass_1" type="box" size="0.75 0.02 0.95" pos="3 5.95 2.5" material="mat_glass" contype="0" conaffinity="0"/>
        <light name="window_light_1" pos="3 6.5 2.5" dir="0 -1 0" diffuse="0.5 0.6 0.7" cutoff="60" castshadow="false"/>

        <!-- 窗户2 -->
        <geom name="window_frame_2" type="box" size="0.8 0.05 1.0" pos="0.5 5.95 2.5" material="mat_wood"/>
        <geom name="window_glass_2" type="box" size="0.75 0.02 0.95" pos="0.5 5.95 2.5" material="mat_glass" contype="0" conaffinity="0"/>
        <light name="window_light_2" pos="0.5 6.5 2.5" dir="0 -1 0" diffuse="0.5 0.6 0.7" cutoff="60" castshadow="false"/>

        <!-- 窗户3 -->
        <geom name="window_frame_3" type="box" size="0.8 0.05 1.0" pos="-2 5.95 2.5" material="mat_wood"/>
        <geom name="window_glass_3" type="box" size="0.75 0.02 0.95" pos="-2 5.95 2.5" material="mat_glass" contype="0" conaffinity="0"/>
        <light name="window_light_3" pos="-2 6.5 2.5" dir="0 -1 0" diffuse="0.5 0.6 0.7" cutoff="60" castshadow="false"/>

        <!-- 窗户4 -->
        <geom name="window_frame_4" type="box" size="0.8 0.05 1.0" pos="-4.5 5.95 2.5" material="mat_wood"/>
        <geom name="window_glass_4" type="box" size="0.75 0.02 0.95" pos="-4.5 5.95 2.5" material="mat_glass" contype="0" conaffinity="0"/>
        <light name="window_light_4" pos="-4.5 6.5 2.5" dir="0 -1 0" diffuse="0.5 0.6 0.7" cutoff="60" castshadow="false"/>

        <geom name="podium" type="box" size="0.35 0.5 0.55" pos="4.5 2.5 0.55" material="mat_wood"/>
        <geom name="desk_1" type="box" size="0.4 2.5 0.02" pos="2.2 0 0.75" material="mat_wood"/>
        <geom name="desk_2" type="box" size="0.4 2.5 0.02" pos="0.5 0 0.75" material="mat_wood"/>
        <geom name="desk_3" type="box" size="0.4 2.5 0.02" pos="-1.2 0 0.75" material="mat_wood"/>
        
        <body name="chair_interactive" pos="1.5 0 0">
            <freejoint/>
            <geom name="seat" type="box" size="0.2 0.2 0.02" pos="0 0 0.45" material="mat_wood" mass="2"/>
            <geom name="backrest" type="box" size="0.02 0.2 0.25" pos="-0.18 0 0.7" material="mat_wood" mass="1"/>
            <geom name="leg1" type="cylinder" size="0.015 0.22" pos="0.16 0.16 0.22" rgba="0.1 0.1 0.1 1" mass="0.3"/>
            <geom name="leg2" type="cylinder" size="0.015 0.22" pos="-0.16 0.16 0.22" rgba="0.1 0.1 0.1 1" mass="0.3"/>
            <geom name="leg3" type="cylinder" size="0.015 0.22" pos="0.16 -0.16 0.22" rgba="0.1 0.1 0.1 1" mass="0.3"/>
            <geom name="leg4" type="cylinder" size="0.015 0.22" pos="-0.16 -0.16 0.22" rgba="0.1 0.1 0.1 1" mass="0.3"/>
        </body>

        <body name="chair_2" pos="-0.2 0 0">
            <freejoint/>
            <geom name="seat2" type="box" size="0.2 0.2 0.02" pos="0 0 0.45" material="mat_wood" mass="2"/>
            <geom name="backrest2" type="box" size="0.02 0.2 0.25" pos="-0.18 0 0.7" material="mat_wood" mass="1"/>
            <geom name="leg2_1" type="cylinder" size="0.015 0.22" pos="0.16 0.16 0.22" rgba="0.1 0.1 0.1 1" mass="0.3"/>
            <geom name="leg2_2" type="cylinder" size="0.015 0.22" pos="-0.16 0.16 0.22" rgba="0.1 0.1 0.1 1" mass="0.3"/>
            <geom name="leg2_3" type="cylinder" size="0.015 0.22" pos="0.16 -0.16 0.22" rgba="0.1 0.1 0.1 1" mass="0.3"/>
            <geom name="leg2_4" type="cylinder" size="0.015 0.22" pos="-0.16 -0.16 0.22" rgba="0.1 0.1 0.1 1" mass="0.3"/>
        </body>

        <body name="chair_3" pos="-1.9 0 0">
            <freejoint/>
            <geom name="seat3" type="box" size="0.2 0.2 0.02" pos="0 0 0.45" material="mat_wood" mass="2"/>
            <geom name="backrest3" type="box" size="0.02 0.2 0.25" pos="-0.18 0 0.7" material="mat_wood" mass="1"/>
            <geom name="leg3_1" type="cylinder" size="0.015 0.22" pos="0.16 0.16 0.22" rgba="0.1 0.1 0.1 1" mass="0.3"/>
            <geom name="leg3_2" type="cylinder" size="0.015 0.22" pos="-0.16 0.16 0.22" rgba="0.1 0.1 0.1 1" mass="0.3"/>
            <geom name="leg3_3" type="cylinder" size="0.015 0.22" pos="0.16 -0.16 0.22" rgba="0.1 0.1 0.1 1" mass="0.3"/>
            <geom name="leg3_4" type="cylinder" size="0.015 0.22" pos="-0.16 -0.16 0.22" rgba="0.1 0.1 0.1 1" mass="0.3"/>
        </body>

        <body name="book" pos="2.2 0.5 0.82">
            <freejoint/>
            <geom size="0.12 0.09 0.02" rgba="0.2 0.4 0.8 1" type="box" mass="0.5"/>
        </body>

        <!-- 可翻开的书（带动画效果） -->
        <body name="open_book" pos="2.2 -0.2 0.78">
            <freejoint/>
            <!-- 书脊和底座 -->
            <geom name="book_spine" type="box" size="0.01 0.12 0.001" pos="0 0 0" rgba="0.6 0.3 0.1 1" mass="0.1"/>

            <!-- 左页 -->
            <body name="left_page" pos="-0.07 0 0.001">
                <joint name="left_page_hinge" type="hinge" axis="0 1 0" pos="0.06 0 0" range="-90 90" damping="0.1"/>
                <geom name="left_page_geom" type="box" size="0.06 0.12 0.0005" pos="0 0 0" rgba="0.95 0.93 0.88 1" mass="0.05"/>
            </body>

            <!-- 右页 -->
            <body name="right_page" pos="0.07 0 0.001">
                <joint name="right_page_hinge" type="hinge" axis="0 1 0" pos="-0.06 0 0" range="-90 90" damping="0.1"/>
                <geom name="right_page_geom" type="box" size="0.06 0.12 0.0005" pos="0 0 0" rgba="0.95 0.93 0.88 1" mass="0.05"/>
            </body>
        </body>

        <body name="cup" pos="2.2 -0.5 0.82">
            <freejoint/>
            <geom size="0.03 0.07" rgba="0.9 0.9 1 0.5" type="cylinder" mass="0.2"/>
        </body>

        <!-- 黑板 -->
        <geom name="blackboard" type="box" size="0.02 1.5 1.0" pos="5.5 0 2.0" material="mat_blackboard"/>

        <!-- 投影幕布 (卷起状态) -->
        <geom name="screen_case" type="cylinder" size="0.05 1.5" pos="5.3 0 2.8" quat="0.707 0 0.707 0" material="mat_plastic"/>

        <!-- 投影幕布 (展开状态，固定在墙上) -->
        <body name="projector_screen" pos="5.4 0 2.0">
            <geom name="screen_surface" type="box" size="0.01 1.2 0.9" material="mat_screen" mass="1.5"/>
        </body>

        <!-- 投影仪 (固定在天花板) -->
        <body name="projector" pos="0 0 2.7">
            <geom name="projector_body" type="box" size="0.15 0.12 0.08" material="mat_plastic" mass="2.5"/>
            <geom name="projector_lens" type="cylinder" size="0.03 0.02" pos="0.15 0 0" quat="0.707 0 0.707 0" rgba="0.1 0.1 0.15 0.8" mass="0.1"/>
        </body>

        <!-- 讲台上的笔记本电脑 -->
        <body name="laptop" pos="4.5 2.5 0.62">
            <freejoint/>
            <geom name="laptop_base" type="box" size="0.15 0.1 0.01" rgba="0.15 0.15 0.15 1" mass="0.8"/>
            <geom name="laptop_screen" type="box" size="0.15 0.005 0.12" pos="0 -0.08 0.11" quat="0.966 0.259 0 0" rgba="0.1 0.1 0.1 1" mass="0.4"/>
        </body>

        <!-- 书架 -->
        <geom name="bookshelf_back" type="box" size="0.02 0.8 1.2" pos="-4.8 -3.0 1.2" material="mat_wood"/>
        <geom name="bookshelf_bottom" type="box" size="0.15 0.8 0.02" pos="-4.65 -3.0 0.4" material="mat_wood"/>
        <geom name="bookshelf_mid1" type="box" size="0.15 0.8 0.02" pos="-4.65 -3.0 0.9" material="mat_wood"/>
        <geom name="bookshelf_mid2" type="box" size="0.15 0.8 0.02" pos="-4.65 -3.0 1.4" material="mat_wood"/>
        <geom name="bookshelf_top" type="box" size="0.15 0.8 0.02" pos="-4.65 -3.0 1.9" material="mat_wood"/>

        <!-- 书架上的书籍 -->
        <body name="book_2" pos="-4.6 -3.3 0.45">
            <freejoint/>
            <geom type="box" size="0.08 0.12 0.03" rgba="0.8 0.2 0.2 1" mass="0.6"/>
        </body>
        <body name="book_3" pos="-4.6 -3.1 0.45">
            <freejoint/>
            <geom type="box" size="0.08 0.12 0.03" rgba="0.2 0.6 0.3 1" mass="0.5"/>
        </body>
        <body name="book_4" pos="-4.6 -2.9 0.45">
            <freejoint/>
            <geom type="box" size="0.08 0.12 0.03" rgba="0.9 0.7 0.1 1" mass="0.55"/>
        </body>
        <body name="book_5" pos="-4.6 -3.3 0.95">
            <freejoint/>
            <geom type="box" size="0.1 0.14 0.025" rgba="0.4 0.2 0.6 1" mass="0.7"/>
        </body>
        <body name="book_6" pos="-4.6 -3.0 0.95">
            <freejoint/>
            <geom type="box" size="0.09 0.13 0.02" rgba="0.1 0.3 0.5 1" mass="0.45"/>
        </body>

        <!-- 桌面上更多书籍 -->
        <body name="book_stack_1" pos="2.2 1.0 0.82">
            <freejoint/>
            <geom type="box" size="0.11 0.08 0.04" rgba="0.6 0.4 0.2 1" mass="0.8"/>
        </body>
        <body name="book_stack_2" pos="2.2 1.2 0.82">
            <freejoint/>
            <geom type="box" size="0.10 0.07 0.035" rgba="0.3 0.5 0.7 1" mass="0.6"/>
        </body>

        <!-- 文具用品 -->
        <body name="pencil_case" pos="2.2 -1.0 0.78">
            <freejoint/>
            <geom type="box" size="0.08 0.04 0.02" rgba="0.8 0.3 0.5 1" mass="0.15"/>
        </body>

        <body name="pen_1" pos="2.2 -1.3 0.77">
            <freejoint/>
            <geom type="cylinder" size="0.004 0.07" rgba="0.1 0.1 0.8 1" mass="0.01"/>
        </body>

        <body name="pen_2" pos="2.2 -1.35 0.77">
            <freejoint/>
            <geom type="cylinder" size="0.004 0.07" rgba="0.8 0.1 0.1 1" mass="0.01"/>
        </body>

        <body name="notebook" pos="2.2 -1.8 0.77">
            <freejoint/>
            <geom type="box" size="0.10 0.14 0.01" rgba="0.9 0.9 0.7 1" mass="0.3"/>
        </body>

        <!-- 讲台上的教学用品 -->
        <body name="chalk_box" pos="4.5 2.0 0.62">
            <freejoint/>
            <geom type="box" size="0.06 0.04 0.025" rgba="0.9 0.85 0.7 1" mass="0.1"/>
        </body>

        <body name="eraser" pos="4.3 2.3 0.58">
            <freejoint/>
            <geom type="box" size="0.05 0.03 0.015" rgba="0.95 0.95 0.8 1" mass="0.05"/>
        </body>

        <body name="marker_1" pos="4.4 1.8 0.57">
            <freejoint/>
            <geom type="cylinder" size="0.008 0.06" rgba="0.1 0.1 0.1 1" mass="0.02"/>
        </body>

        <!-- 水瓶 -->
        <body name="water_bottle" pos="4.7 2.5 0.58">
            <freejoint/>
            <geom name="bottle_body" type="cylinder" size="0.035 0.10" rgba="0.7 0.9 1.0 0.6" mass="0.5"/>
            <geom name="bottle_cap" type="cylinder" size="0.025 0.015" pos="0 0 0.115" rgba="0.2 0.4 0.8 1" mass="0.02"/>
        </body>

        <!-- 垃圾桶 -->
        <body name="trash_bin" pos="-4.5 3.5 0.25">
            <freejoint/>
            <geom type="cylinder" size="0.15 0.25" rgba="0.3 0.3 0.3 1" mass="1.5"/>
        </body>

        <!-- 时钟 (挂在墙上) -->
        <geom name="clock" type="cylinder" size="0.2 0.03" pos="5.6 3.5 2.5" quat="0.707 0 0.707 0" material="mat_plastic"/>
        <geom name="clock_face" type="cylinder" size="0.18 0.01" pos="5.65 3.5 2.5" quat="0.707 0 0.707 0" rgba="1 1 1 1"/>

        <!-- 文件夹 -->
        <body name="folder_1" pos="2.2 1.8 0.77">
            <freejoint/>
            <geom type="box" size="0.12 0.15 0.005" rgba="0.9 0.7 0.2 1" mass="0.2"/>
        </body>

        <body name="folder_2" pos="4.2 2.7 0.57">
            <freejoint/>
            <geom type="box" size="0.11 0.14 0.005" rgba="0.3 0.6 0.9 1" mass="0.18"/>
        </body>

        <!-- 笔筒 -->
        <body name="pen_holder" pos="4.7 2.0 0.58">
            <freejoint/>
            <geom type="cylinder" size="0.04 0.06" rgba="0.6 0.3 0.2 1" mass="0.3"/>
        </body>

        <!-- 计算器 -->
        <body name="calculator" pos="2.2 -2.2 0.77">
            <freejoint/>
            <geom type="box" size="0.04 0.07 0.008" rgba="0.15 0.15 0.15 1" mass="0.15"/>
        </body>

        <!-- 订书机 -->
        <body name="stapler" pos="4.3 1.9 0.57">
            <freejoint/>
            <geom type="box" size="0.05 0.025 0.015" material="mat_metal" mass="0.25"/>
        </body>

        <!-- 胶带座 -->
        <body name="tape_dispenser" pos="4.8 1.8 0.58">
            <freejoint/>
            <geom name="tape_base" type="box" size="0.04 0.06 0.02" material="mat_plastic" mass="0.2"/>
            <geom name="tape_roll" type="cylinder" size="0.025 0.01" pos="0 0.02 0.025" quat="0.707 0.707 0 0" rgba="0.9 0.9 0.7 0.7" mass="0.05"/>
        </body>

        <!-- 眼镜 -->
        <body name="glasses" pos="2.2 0.2 0.78">
            <freejoint/>
            <geom type="box" size="0.06 0.02 0.005" rgba="0.1 0.1 0.1 0.5" mass="0.03"/>
        </body>

        <!-- desk_2 上的物品 -->
        <body name="book_desk2_1" pos="0.5 0.6 0.82">
            <freejoint/>
            <geom type="box" size="0.11 0.09 0.025" rgba="0.7 0.3 0.2 1" mass="0.55"/>
        </body>

        <body name="book_desk2_2" pos="0.5 1.2 0.82">
            <freejoint/>
            <geom type="box" size="0.10 0.08 0.02" rgba="0.3 0.6 0.4 1" mass="0.5"/>
        </body>

        <body name="pencil_desk2" pos="0.5 -0.8 0.77">
            <freejoint/>
            <geom type="cylinder" size="0.004 0.08" rgba="0.9 0.7 0.1 1" mass="0.01"/>
        </body>

        <body name="notebook_desk2" pos="0.5 -1.5 0.77">
            <freejoint/>
            <geom type="box" size="0.12 0.15 0.01" rgba="0.8 0.9 0.7 1" mass="0.35"/>
        </body>

        <body name="eraser_desk2" pos="0.5 -0.3 0.77">
            <freejoint/>
            <geom type="box" size="0.03 0.02 0.01" rgba="0.9 0.6 0.6 1" mass="0.02"/>
        </body>

        <body name="ruler_desk2" pos="0.5 0 0.77">
            <freejoint/>
            <geom type="box" size="0.15 0.015 0.002" rgba="0.9 0.9 0.5 0.6" mass="0.03"/>
        </body>

        <body name="cup_desk2" pos="0.5 2.0 0.82">
            <freejoint/>
            <geom type="cylinder" size="0.035 0.08" rgba="0.8 0.4 0.3 0.8" mass="0.25"/>
        </body>

        <!-- desk_3 上的物品 -->
        <body name="book_desk3_1" pos="-1.2 0.8 0.82">
            <freejoint/>
            <geom type="box" size="0.12 0.10 0.03" rgba="0.5 0.2 0.7 1" mass="0.65"/>
        </body>

        <body name="book_desk3_2" pos="-1.2 1.5 0.82">
            <freejoint/>
            <geom type="box" size="0.09 0.12 0.025" rgba="0.1 0.5 0.6 1" mass="0.55"/>
        </body>

        <body name="book_desk3_3" pos="-1.2 0.3 0.82">
            <freejoint/>
            <geom type="box" size="0.08 0.11 0.02" rgba="0.8 0.6 0.2 1" mass="0.45"/>
        </body>

        <body name="pencil_case_desk3" pos="-1.2 -1.2 0.78">
            <freejoint/>
            <geom type="box" size="0.09 0.045 0.025" rgba="0.3 0.5 0.8 1" mass="0.18"/>
        </body>

        <body name="pen_desk3_1" pos="-1.2 -0.5 0.77">
            <freejoint/>
            <geom type="cylinder" size="0.004 0.07" rgba="0.2 0.7 0.2 1" mass="0.01"/>
        </body>

        <body name="pen_desk3_2" pos="-1.2 -0.55 0.77">
            <freejoint/>
            <geom type="cylinder" size="0.004 0.07" rgba="0.1 0.1 0.1 1" mass="0.01"/>
        </body>

        <body name="folder_desk3" pos="-1.2 2.0 0.77">
            <freejoint/>
            <geom type="box" size="0.11 0.13 0.005" rgba="0.7 0.3 0.5 1" mass="0.2"/>
        </body>

        <body name="scissors_desk3" pos="-1.2 -1.8 0.77">
            <freejoint/>
            <geom type="box" size="0.04 0.08 0.005" rgba="0.5 0.5 0.6 1" mass="0.08"/>
        </body>

        <body name="glue_desk3" pos="-1.2 -2.2 0.78">
            <freejoint/>
            <geom type="cylinder" size="0.02 0.05" rgba="0.9 0.9 0.95 0.8" mass="0.1"/>
        </body>

    </worldbody>

    <actuator>
        <!-- 书页翻动控制器 -->
        <position name="left_page_actuator" joint="left_page_hinge" kp="5" ctrlrange="-90 90"/>
        <position name="right_page_actuator" joint="right_page_hinge" kp="5" ctrlrange="-90 90"/>

        <!-- 门开关控制器 -->
        <position name="door_actuator" joint="door_hinge" kp="50" ctrlrange="0 120"/>
    </actuator>
</mujoco>